[
    {
        "message": "Module error while trying to sync data with repo: git command failed: Command '['git', 'pull', 'origin', 'main']' returned non-zero exit status 1. (CalledProcessError).",
        "severity": 2,
        "origin": "data_uploader.py:9 --> project.py/sync_dir_with_repo:257",
        "origin_timestamp": "2024-09-23-12-00-04",
        "registration_timestamp": "2024-09-23-12-00-04",
        "reported": true,
        "reported_timestamp": "2024-09-23-16-00-02",
        "checked": false,
        "checked_timestamp": null
    },
    {
        "message": "Module error while trying to update local copy of weekly cycle for Oktopusz.: couldn't export 2D array to CSV at config/local_scheduling_files/weekly_cycle_Oktopusz.csv: 'charmap' codec can't encode character '\\u0151' in position 5: character maps to <undefined> (UnicodeEncodeError).",
        "severity": 3,
        "origin": "schedule_and_ config_updater.py/update_local_scheduling_files:53 --> project.py/export_2D_array_to_csv:1106",
        "origin_timestamp": "2024-10-05-14-00-44",
        "registration_timestamp": "2024-10-05-14-00-44",
        "reported": true,
        "reported_timestamp": "2024-10-05-19-10-19",
        "checked": false,
        "checked_timestamp": null
    },
    {
        "message": "Module error while trying to update room overrides.: couldn't export 2D array to CSV at config/local_scheduling_files/override_rooms.csv: 'charmap' codec can't encode character '\\u0151' in position 53: character maps to <undefined> (UnicodeEncodeError).",
        "severity": 3,
        "origin": "schedule_and_ config_updater.py/update_local_scheduling_files:70 --> project.py/export_2D_array_to_csv:1106",
        "origin_timestamp": "2024-10-05-14-01-05",
        "registration_timestamp": "2024-10-05-14-01-05",
        "reported": true,
        "reported_timestamp": "2024-10-05-19-10-21",
        "checked": false,
        "checked_timestamp": null
    },
    {
        "message": "Module error while trying to update cycle overrides.: couldn't export 2D array to CSV at config/local_scheduling_files/override_cycles.csv: 'charmap' codec can't encode character '\\u0151' in position 60: character maps to <undefined> (UnicodeEncodeError).",
        "severity": 3,
        "origin": "schedule_and_ config_updater.py/update_local_scheduling_files:87 --> project.py/export_2D_array_to_csv:1106",
        "origin_timestamp": "2024-10-05-14-01-06",
        "registration_timestamp": "2024-10-05-14-01-06",
        "reported": true,
        "reported_timestamp": "2024-10-05-19-10-24",
        "checked": false,
        "checked_timestamp": null
    },
    {
        "message": "Module error while trying to update local copy of weekly cycle for vend\u00e9gt\u00e9r.: couldn't download csv from https://docs.google.com/spreadsheets/d/1OmcLOB4OvFqmVw6Jq1lxu5fo7FchPBNMM6MFoNgM7r4/pub?output=csv&2020257900:  (KeyboardInterrupt).",
        "severity": 3,
        "origin": "schedule_and_ config_updater.py/update_local_scheduling_files:53 --> project.py/download_csv_to_2D_array:1014",
        "origin_timestamp": "2024-10-05-14-01-42",
        "registration_timestamp": "2024-10-05-14-01-42",
        "reported": true,
        "reported_timestamp": "2024-10-05-19-10-27",
        "checked": false,
        "checked_timestamp": null
    },
    {
        "message": "Module error while trying to update room overrides.: couldn't download csv from https://docs.google.com/spreadsheets/d/1Cir4TYYhIx14Qja9c4nN9m2GTeZ0FHrJRt03oXs_fgI/pub?output=csv:  (KeyboardInterrupt).",
        "severity": 3,
        "origin": "schedule_and_ config_updater.py/update_local_scheduling_files:70 --> project.py/download_csv_to_2D_array:1014",
        "origin_timestamp": "2024-10-05-14-01-44",
        "registration_timestamp": "2024-10-05-14-01-44",
        "reported": true,
        "reported_timestamp": "2024-10-05-19-10-28",
        "checked": false,
        "checked_timestamp": null
    },
    {
        "message": "Module error while trying to update cycle overrides.: couldn't download csv from https://docs.google.com/spreadsheets/d/1U0QnnC-E0hrbp0pf5foDVTwHQTmSteIG8vXHI6MXkh8/pub?output=csv:  (KeyboardInterrupt).",
        "severity": 3,
        "origin": "schedule_and_ config_updater.py/update_local_scheduling_files:87 --> project.py/download_csv_to_2D_array:1014",
        "origin_timestamp": "2024-10-05-14-01-44",
        "registration_timestamp": "2024-10-05-14-01-44",
        "reported": true,
        "reported_timestamp": "2024-10-05-19-10-30",
        "checked": false,
        "checked_timestamp": null
    },
    {
        "message": "Unexpected error while trying to update room overrides.: cannot access local variable 'response' where it is not associated with a value.",
        "severity": 3,
        "origin": "schedule_and_ config_updater.py/update_local_scheduling_files:78 --> project.py/write:253 --> project.py/interact:232",
        "origin_timestamp": "2024-10-05-14-30-28",
        "registration_timestamp": "2024-10-05-14-30-28",
        "reported": true,
        "reported_timestamp": "2024-10-05-19-10-32",
        "checked": false,
        "checked_timestamp": null
    },
    {
        "message": "Module error while trying to update local copy of weekly_cycle/1.: couldn't export 2D array to CSV at config/local_scheduling_files/weekly_cycle_Oktopusz.csv: [Errno 2] No such file or directory: 'C:\\\\Users\\\\Beno\\\\Documents\\\\SZAKI\\\\dev\\\\kazanfutes\\\\config/local_scheduling_files/weekly_cycle_Oktopusz.csv' (FileNotFoundError).",
        "severity": 3,
        "origin": "schedule_and_ config_updater.py/update_local_scheduling_files:77 --> project.py/export_2D_array_to_csv:1138",
        "origin_timestamp": "2024-10-05-15-48-57",
        "registration_timestamp": "2024-10-05-15-48-57",
        "reported": true,
        "reported_timestamp": "2024-10-05-19-10-35",
        "checked": false,
        "checked_timestamp": null
    },
    {
        "message": "Module error while trying to update local copy of weekly_cycle/4.: couldn't download csv from https://docs.google.com/spreadsheets/d/1OmcLOB4OvFqmVw6Jq1lxu5fo7FchPBNMM6MFoNgM7r4/pub?output=csv&gid=228406814:  (KeyboardInterrupt).",
        "severity": 3,
        "origin": "schedule_and_ config_updater.py/update_local_scheduling_files:77 --> project.py/download_csv_to_2D_array:1046",
        "origin_timestamp": "2024-10-05-15-49-01",
        "registration_timestamp": "2024-10-05-15-49-01",
        "reported": true,
        "reported_timestamp": "2024-10-05-19-10-38",
        "checked": false,
        "checked_timestamp": null
    },
    {
        "message": "Module error while trying to update local copy of weekly_cycle/G\u00f3lyairoda.: couldn't download csv from None: Invalid URL 'None': No scheme supplied. Perhaps you meant https://None? (MissingSchema).",
        "severity": 3,
        "origin": "schedule_and_ config_updater.py/update_local_scheduling_files:90 --> project.py/download_csv_to_2D_array:1055",
        "origin_timestamp": "2024-10-05-18-21-25",
        "registration_timestamp": "2024-10-05-18-21-25",
        "reported": true,
        "reported_timestamp": "2024-10-05-19-10-41",
        "checked": false,
        "checked_timestamp": null
    },
    {
        "message": "Unexpected error while trying to generate condensed schedule.: 'list' object has no attribute 'join'.",
        "severity": 3,
        "origin": "schedule_and_ config_updater.py/generate_and_export_condensed_schedule:169",
        "origin_timestamp": "2024-10-05-18-50-16",
        "registration_timestamp": "2024-10-05-18-50-16",
        "reported": true,
        "reported_timestamp": "2024-10-05-19-10-45",
        "checked": false,
        "checked_timestamp": null
    },
    {
        "message": "Unexpected error while trying to generate condensed schedule.: 'list' object has no attribute 'join'.",
        "severity": 3,
        "origin": "schedule_and_ config_updater.py/generate_and_export_condensed_schedule:170",
        "origin_timestamp": "2024-10-05-18-52-38",
        "registration_timestamp": "2024-10-05-18-52-38",
        "reported": true,
        "reported_timestamp": "2024-10-05-19-10-46",
        "checked": false,
        "checked_timestamp": null
    },
    {
        "message": "Unexpected error while trying to generate condensed schedule.: 'list' object has no attribute 'join'.",
        "severity": 3,
        "origin": "schedule_and_ config_updater.py/generate_and_export_condensed_schedule:171",
        "origin_timestamp": "2024-10-05-18-56-17",
        "registration_timestamp": "2024-10-05-18-56-17",
        "reported": true,
        "reported_timestamp": "2024-10-05-19-10-47",
        "checked": false,
        "checked_timestamp": null
    },
    {
        "message": "Module error while trying to generate condensed schedule.: couldn't load csv from config/local_scheduling_files/weekly_cycle_Lahmacun.csv:  (KeyboardInterrupt).",
        "severity": 3,
        "origin": "schedule_and_ config_updater.py/generate_and_export_condensed_schedule:149 --> project.py/load_csv_to_2D_array:1068",
        "origin_timestamp": "2024-10-05-18-56-30",
        "registration_timestamp": "2024-10-05-18-56-30",
        "reported": true,
        "reported_timestamp": "2024-10-05-19-10-50",
        "checked": false,
        "checked_timestamp": null
    },
    {
        "message": "Unexpected error while trying to update local heating control config: 'heating_control_config_url'.",
        "severity": 2,
        "origin": "schedule_and_ config_updater.py/update_local_heating_control_config:42",
        "origin_timestamp": "2024-10-05-19-34-14",
        "registration_timestamp": "2024-10-05-19-34-14",
        "reported": true,
        "reported_timestamp": "2024-10-06-01-08-41",
        "checked": false,
        "checked_timestamp": null
    },
    {
        "message": "Unexpected error while trying to update local heating control config: 'heating_control_config_url'.",
        "severity": 2,
        "origin": "schedule_and_ config_updater.py/update_local_heating_control_config:46",
        "origin_timestamp": "2024-10-05-19-52-47",
        "registration_timestamp": "2024-10-05-19-52-47",
        "reported": true,
        "reported_timestamp": "2024-10-06-01-08-41",
        "checked": false,
        "checked_timestamp": null
    },
    {
        "message": "Unexpected error while trying to initialize heating control: strptime() takes exactly 2 arguments (1 given).",
        "severity": 3,
        "origin": "heating_control.py/compare_and_command:56 --> project.py/get_room_temps_and_humidity_dev:703",
        "origin_timestamp": "2024-10-05-20-37-04",
        "registration_timestamp": "2024-10-05-20-37-04",
        "reported": true,
        "reported_timestamp": "2024-10-06-01-08-41",
        "checked": false,
        "checked_timestamp": null
    },
    {
        "message": "Unexpected error while trying to initialize heating control: strptime() takes exactly 2 arguments (1 given).",
        "severity": 3,
        "origin": "heating_control.py/compare_and_command:57 --> project.py/get_room_temps_and_humidity_dev:703",
        "origin_timestamp": "2024-10-05-20-37-18",
        "registration_timestamp": "2024-10-05-20-37-18",
        "reported": true,
        "reported_timestamp": "2024-10-06-01-08-41",
        "checked": false,
        "checked_timestamp": null
    },
    {
        "message": "Module error while trying to update local heating control config: couldn't download csv from https://docs.google.com/spreadsheets/d/e/2PACX-1vQesA7RtQho9HwcVSOitNyLRDn6oODG5K7-s6C85kWOLwcz7yiGg2d_SuBYhoCkDAVUQ0vXGzaa12dn/pub?output=csv:  (KeyboardInterrupt).",
        "severity": 2,
        "origin": "schedule_and_ config_updater.py/update_local_heating_control_config:48 --> project.py/download_csv_to_2D_array:1081",
        "origin_timestamp": "2024-10-05-22-39-29",
        "registration_timestamp": "2024-10-05-22-39-29",
        "reported": true,
        "reported_timestamp": "2024-10-06-01-08-41",
        "checked": false,
        "checked_timestamp": null
    },
    {
        "message": "Module error while trying to update local copy of weekly_cycle/1: couldn't download csv from https://docs.google.com/spreadsheets/d/1OmcLOB4OvFqmVw6Jq1lxu5fo7FchPBNMM6MFoNgM7r4/pub?output=csv&gid=1887663707:  (KeyboardInterrupt).",
        "severity": 3,
        "origin": "schedule_and_ config_updater.py/update_local_scheduling_files:129 --> project.py/download_csv_to_2D_array:1081",
        "origin_timestamp": "2024-10-05-22-39-32",
        "registration_timestamp": "2024-10-05-22-39-32",
        "reported": true,
        "reported_timestamp": "2024-10-06-01-08-41",
        "checked": false,
        "checked_timestamp": null
    },
    {
        "message": "Module error while trying to update local copy of weekly_cycle/1: couldn't export 2D array to CSV at config/local_scheduling_files/weekly_cycle_room_{'name': 'Oktopusz', 'sensor': None, 'cycle': '1', 'schedule_gid': '1887663707'}.csv: [Errno 22] Invalid argument: \"C:\\\\Users\\\\Beno\\\\Documents\\\\SZAKI\\\\dev\\\\kazanfutes\\\\config/local_scheduling_files/weekly_cycle_room_{'name': 'Oktopusz', 'sensor': None, 'cycle': '1', 'schedule_gid': '1887663707'}.csv\" (OSError).",
        "severity": 3,
        "origin": "schedule_and_ config_updater.py/update_local_scheduling_files:129 --> project.py/export_2D_array_to_csv:1297",
        "origin_timestamp": "2024-10-06-19-22-33",
        "registration_timestamp": "2024-10-06-19-22-33",
        "reported": true,
        "reported_timestamp": "2024-10-07-00-00-02",
        "checked": false,
        "checked_timestamp": null
    },
    {
        "message": "Module error while trying to generate condensed schedule: couldn't load csv from config/local_scheduling_files/weekly_cycle_room_{'name': 'Oktopusz', 'sensor': None, 'cycle': '1', 'schedule_gid': '1887663707'}.csv: [Errno 22] Invalid argument: \"C:\\\\Users\\\\Beno\\\\Documents\\\\SZAKI\\\\dev\\\\kazanfutes\\\\config/local_scheduling_files/weekly_cycle_room_{'name': 'Oktopusz', 'sensor': None, 'cycle': '1', 'schedule_gid': '1887663707'}.csv\" (OSError).",
        "severity": 3,
        "origin": "schedule_and_ config_updater.py/generate_condensed_schedule:183 --> project.py/load_csv_to_2D_array:1210",
        "origin_timestamp": "2024-10-06-19-22-33",
        "registration_timestamp": "2024-10-06-19-22-33",
        "reported": true,
        "reported_timestamp": "2024-10-07-00-00-02",
        "checked": false,
        "checked_timestamp": null
    },
    {
        "message": "Module error while trying to update local copy of weekly_cycle/8: couldn't download csv from https://docs.google.com/spreadsheets/d/1OmcLOB4OvFqmVw6Jq1lxu5fo7FchPBNMM6MFoNgM7r4/pub?output=csv&gid=60517023:  (KeyboardInterrupt).",
        "severity": 3,
        "origin": "schedule_and_ config_updater.py/update_local_scheduling_files:129 --> project.py/download_csv_to_2D_array:1197",
        "origin_timestamp": "2024-10-06-19-22-33",
        "registration_timestamp": "2024-10-06-19-22-33",
        "reported": true,
        "reported_timestamp": "2024-10-07-00-00-02",
        "checked": false,
        "checked_timestamp": null
    },
    {
        "message": "Module error while trying to acquire temperature and humidity data: unexpected error while reading sensor state: time data 'none' does not match format '%Y-%m-%dT%H:%M:%S.%f' (ValueError).",
        "severity": 3,
        "origin": "temperature_and_humidity_logger.py:10 --> project.py/get_room_temps_and_humidity:734",
        "origin_timestamp": "2024-10-10-15-25-01",
        "registration_timestamp": "2024-10-10-15-25-01",
        "reported": true,
        "reported_timestamp": "2024-10-10-16-00-02",
        "checked": false,
        "checked_timestamp": null
    },
    {
        "message": "Module error while trying to acquire temperature and humidity data: unexpected error while reading sensor state: 'Multiple conflicting time zone configurations found:\\n/etc/timezone: Europe/London\\n/etc/localtime is a symlink to: Europe/Budapest\\nFix the configuration, or set the time zone in a TZ environment variable.\\n' (ZoneInfoNotFoundError).",
        "severity": 3,
        "origin": "temperature_and_humidity_logger.py:10 --> project.py/get_room_temps_and_humidity:741",
        "origin_timestamp": "2024-10-11-14-05-02",
        "registration_timestamp": "2024-10-11-14-05-02",
        "reported": true,
        "reported_timestamp": "2024-10-11-16-00-03",
        "checked": false,
        "checked_timestamp": null
    },
    {
        "message": "Module error while trying to update local copy of weekly_cycle/4: couldn't download csv from https://docs.google.com/spreadsheets/d/1OmcLOB4OvFqmVw6Jq1lxu5fo7FchPBNMM6MFoNgM7r4/pub?output=csv&gid=228406814: ('Connection aborted.', ConnectionAbortedError(10053, 'An established connection was aborted by the software in your host machine', None, 10053, None)) (ConnectionError).",
        "severity": 3,
        "origin": "schedule_and_ config_updater.py/update_local_scheduling_files:131 --> project.py/download_csv_to_2D_array:1497",
        "origin_timestamp": "2024-10-14-17-08-39",
        "registration_timestamp": "2024-10-14-17-08-39",
        "reported": true,
        "reported_timestamp": "2024-10-14-20-00-02",
        "checked": false,
        "checked_timestamp": null
    },
    {
        "message": "Unexpected error while trying to update local heating control config: cannot access local variable 'spreadsheet_metadata' where it is not associated with a value.",
        "severity": 2,
        "origin": "schedule_and_ config_updater.py/update_local_heating_control_config:56 --> project.py/download_google_sheet_to_2D_array:1523",
        "origin_timestamp": "2024-10-14-21-45-35",
        "registration_timestamp": "2024-10-14-21-45-35",
        "reported": true,
        "reported_timestamp": "2024-10-15-00-00-03",
        "checked": false,
        "checked_timestamp": null
    },
    {
        "message": "Unexpected error while trying to update local copy of weekly_cycle/1: download_csv_to_2D_array() takes 1 positional argument but 2 were given.",
        "severity": 3,
        "origin": "schedule_and_ config_updater.py/update_local_scheduling_files:138",
        "origin_timestamp": "2024-10-14-21-45-35",
        "registration_timestamp": "2024-10-14-21-45-35",
        "reported": true,
        "reported_timestamp": "2024-10-15-00-00-03",
        "checked": false,
        "checked_timestamp": null
    },
    {
        "message": "Module error while trying to update local copy of override_rooms: failed to set up Google Sheets API: <HttpError 404 when requesting https://sheets.googleapis.com/v4/spreadsheets/https%3A%2F%2Fdocs.google.com%2Fspreadsheets%2Fd%2F1Cir4TYYhIx14Qja9c4nN9m2GTeZ0FHrJRt03oXs_fgI%2Fpub%3Foutput%3Dcsv?alt=json returned \"Requested entity was not found.\". Details: \"Requested entity was not found.\"> (HttpError).",
        "severity": 3,
        "origin": "schedule_and_ config_updater.py/update_local_scheduling_files:138 --> project.py/download_google_sheet_to_2D_array:1501",
        "origin_timestamp": "2024-10-14-21-54-34",
        "registration_timestamp": "2024-10-14-21-54-34",
        "reported": true,
        "reported_timestamp": "2024-10-15-00-00-03",
        "checked": false,
        "checked_timestamp": null
    },
    {
        "message": "Module error while trying to update local copy of weekly_cycle/8: failed to download sheet 'kisterem' from spreadsheet 'f\u0171t\u00e9s heti ciklus 24/25':  (KeyboardInterrupt).",
        "severity": 3,
        "origin": "schedule_and_ config_updater.py/update_local_scheduling_files:138 --> project.py/download_google_sheet_to_2D_array:1523",
        "origin_timestamp": "2024-10-14-22-05-35",
        "registration_timestamp": "2024-10-14-22-05-35",
        "reported": true,
        "reported_timestamp": "2024-10-15-00-00-03",
        "checked": false,
        "checked_timestamp": null
    },
    {
        "message": "Module error while trying to acquire temperature and humidity data: couldn't read sensor state due to: failed to connect to Deconz API due to unexpected error: Error requesting data from 192.168.29.54: Cannot connect to host 192.168.29.54:80 ssl:default [Network is unreachable] (RequestError) (ModuleException).",
        "severity": 3,
        "origin": "temperature_and_humidity_logger.py:10 --> project.py/get_room_temps_and_humidity:775",
        "origin_timestamp": "2024-10-15-09-21-34",
        "registration_timestamp": "2024-10-15-09-21-34",
        "reported": true,
        "reported_timestamp": "2024-10-15-09-21-34",
        "checked": false,
        "checked_timestamp": null
    },
    {
        "message": "Module error while trying to initialize heating control: failed to interact with node 'system' via get: HTTPSConnectionPool(host='kazanfutes-71b78-default-rtdb.europe-west1.firebasedatabase.app', port=443): Max retries exceeded with url: /system/.json (Caused by NameResolutionError(\"<urllib3.connection.HTTPSConnection object at 0xf5766490>: Failed to resolve 'kazanfutes-71b78-default-rtdb.europe-west1.firebasedatabase.app' ([Errno -3] Temporary failure in name resolution)\")) (ConnectionError).",
        "severity": 3,
        "origin": "heating_control.py:15 --> project.py/__init__:240 --> project.py/read:266 --> project.py/interact:260",
        "origin_timestamp": "2024-10-15-09-21-34",
        "registration_timestamp": "2024-10-15-09-21-34",
        "reported": true,
        "reported_timestamp": "2024-10-15-09-21-34",
        "checked": false,
        "checked_timestamp": null
    },
    {
        "message": "Unexpected error while voting: 'measured_temps'.",
        "severity": 3,
        "origin": "heating_control.py/compare_and_command:182",
        "origin_timestamp": "2024-10-15-09-21-34",
        "registration_timestamp": "2024-10-15-09-21-34",
        "reported": true,
        "reported_timestamp": "2024-10-15-09-25-04",
        "checked": false,
        "checked_timestamp": null
    },
    {
        "message": "Unexpected error while issuing commands: name 'COMMANDS_PATH' is not defined.",
        "severity": 3,
        "origin": "heating_control.py/compare_and_command:309",
        "origin_timestamp": "2024-10-15-09-21-34",
        "registration_timestamp": "2024-10-15-09-21-34",
        "reported": true,
        "reported_timestamp": "2024-10-15-09-25-04",
        "checked": false,
        "checked_timestamp": null
    },
    {
        "message": "Unexpected error while executing commands: name 'COMMANDS_PATH' is not defined.",
        "severity": 3,
        "origin": "heating_control.py/execute_commands:372",
        "origin_timestamp": "2024-10-15-09-21-34",
        "registration_timestamp": "2024-10-15-09-21-34",
        "reported": true,
        "reported_timestamp": "2024-10-15-09-25-04",
        "checked": false,
        "checked_timestamp": null
    },
    {
        "message": "Module error while acquiring measured temps: couldn't read sensor state due to: failed to connect to Deconz API due to unexpected error: Error requesting data from 192.168.29.54: Cannot connect to host 192.168.29.54:80 ssl:default [Connect call failed ('192.168.29.54', 80)] (RequestError) (ModuleException).",
        "severity": 3,
        "origin": "heating_control.py/get_and_export_system_state:64 --> project.py/get_room_temps_and_humidity:775",
        "origin_timestamp": "2024-10-15-09-22-19",
        "registration_timestamp": "2024-10-15-09-22-19",
        "reported": true,
        "reported_timestamp": "2024-10-15-09-25-04",
        "checked": false,
        "checked_timestamp": null
    },
    {
        "message": "Unexpected error while issuing commands: cannot access local variable 'pump_votes' where it is not associated with a value.",
        "severity": 3,
        "origin": "heating_control.py/compare_and_command:314",
        "origin_timestamp": "2024-10-15-09-22-19",
        "registration_timestamp": "2024-10-15-09-22-19",
        "reported": true,
        "reported_timestamp": "2024-10-15-09-25-04",
        "checked": false,
        "checked_timestamp": null
    },
    {
        "message": "Module error while acquiring measured temps: unexpected error while reading sensor state: time data 'none' does not match format '%Y-%m-%dT%H:%M:%S.%f' (ValueError).",
        "severity": 3,
        "origin": "heating_control.py/get_and_export_system_state:64 --> project.py/get_room_temps_and_humidity:777",
        "origin_timestamp": "2024-10-15-09-23-02",
        "registration_timestamp": "2024-10-15-09-23-02",
        "reported": true,
        "reported_timestamp": "2024-10-15-09-25-04",
        "checked": false,
        "checked_timestamp": null
    },
    {
        "message": "Unexpected error while exporting system state: name 'system_node' is not defined.",
        "severity": 3,
        "origin": "heating_control.py/get_and_export_system_state:136",
        "origin_timestamp": "2024-10-15-09-21-34",
        "registration_timestamp": "2024-10-15-09-25-04",
        "reported": true,
        "reported_timestamp": "2024-10-15-09-25-04",
        "checked": false,
        "checked_timestamp": null
    },
    {
        "message": "Unexpected error while voting: type datetime.timedelta doesn't define __round__ method.",
        "severity": 3,
        "origin": "heating_control.py/compare_and_command:194",
        "origin_timestamp": "2024-10-15-12-42-49",
        "registration_timestamp": "2024-10-15-12-42-49",
        "reported": true,
        "reported_timestamp": "2024-10-15-12-45-07",
        "checked": false,
        "checked_timestamp": null
    },
    {
        "message": "Unexpected error while issuing commands: cannot access local variable 'pump_votes' where it is not associated with a value.",
        "severity": 3,
        "origin": "heating_control.py/compare_and_command:320",
        "origin_timestamp": "2024-10-15-12-42-49",
        "registration_timestamp": "2024-10-15-12-42-49",
        "reported": true,
        "reported_timestamp": "2024-10-15-12-45-07",
        "checked": false,
        "checked_timestamp": null
    },
    {
        "message": "Module error while trying to capture heatmeter images: couldn't extract cycle crops for None: time data 'None' does not match format '%Y-%m-%d-%H-%M-%S' (ValueError).",
        "severity": 2,
        "origin": "heatmeters_logger.py:15 --> project.py/generate_and_save_cycle_crops:626",
        "origin_timestamp": null,
        "registration_timestamp": null,
        "reported": true,
        "reported_timestamp": "2024-10-15-20-50-04",
        "checked": false,
        "checked_timestamp": null
    },
    {
        "message": "Module error while trying to update local copy of weekly_cycle/4: failed to download sheet 'SZGK' from spreadsheet 'f\u0171t\u00e9s heti ciklus 24/25':  (KeyboardInterrupt).",
        "severity": 3,
        "origin": "schedule_and_config_updater.py/update_local_scheduling_files:167 --> project.py/download_google_sheet_to_2D_array:1533",
        "origin_timestamp": null,
        "registration_timestamp": null,
        "reported": true,
        "reported_timestamp": "2024-10-15-20-50-06",
        "checked": false,
        "checked_timestamp": null
    },
    {
        "message": "Module error while trying to update local copy of weekly_cycle/8: failed to set up Google Sheets API:  (KeyboardInterrupt).",
        "severity": 3,
        "origin": "schedule_and_config_updater.py/update_local_scheduling_files:167 --> project.py/download_google_sheet_to_2D_array:1511",
        "origin_timestamp": null,
        "registration_timestamp": null,
        "reported": true,
        "reported_timestamp": "2024-10-15-20-50-07",
        "checked": false,
        "checked_timestamp": null
    },
    {
        "message": "Module error while trying to sync data and config with repo: git command failed: Command '['git', 'pull', 'origin', 'main']' returned non-zero exit status 1. (CalledProcessError).",
        "severity": 2,
        "origin": "data_and_config_uploader.py:9 --> project.py/sync_dir_with_repo:371",
        "origin_timestamp": "2024-10-16-12-30-06",
        "registration_timestamp": "2024-10-16-12-30-06",
        "reported": true,
        "reported_timestamp": "2024-10-16-12-35-02",
        "checked": false,
        "checked_timestamp": null
    },
    {
        "message": "Module error while acquiring boiler state: couldn't read boiler state: couldn't read state of GPIO pin 4: unexpected error while loading system/GPIO_state.json to dict: Expecting value: line 1 column 1 (char 0) (JSONDecodeError) (ModuleException) (ModuleException).",
        "severity": 3,
        "origin": "heating_control.py/get_and_export_system_state:126 --> project.py/get_boiler_state:635",
        "origin_timestamp": "2024-10-16-17-55-03",
        "registration_timestamp": "2024-10-16-17-55-03",
        "reported": true,
        "reported_timestamp": "2024-10-16-18-00-08",
        "checked": false,
        "checked_timestamp": null
    },
    {
        "message": "Unexpected error while voting: 'boiler_state'.",
        "severity": 3,
        "origin": "heating_control.py/compare_and_command:276",
        "origin_timestamp": "2024-10-16-17-55-03",
        "registration_timestamp": "2024-10-16-17-55-03",
        "reported": true,
        "reported_timestamp": "2024-10-16-18-00-10",
        "checked": false,
        "checked_timestamp": null
    },
    {
        "message": "Unexpected error while issuing commands: 'boiler_state'.",
        "severity": 3,
        "origin": "heating_control.py/compare_and_command:323",
        "origin_timestamp": "2024-10-16-17-55-03",
        "registration_timestamp": "2024-10-16-17-55-03",
        "reported": true,
        "reported_timestamp": "2024-10-16-18-00-11",
        "checked": false,
        "checked_timestamp": null
    },
    {
        "message": "Module error while exporting system state: failed to interact with node 'system' via patch: HTTPSConnectionPool(host='kazanfutes-71b78-default-rtdb.europe-west1.firebasedatabase.app', port=443): Max retries exceeded with url: /system/state.json (Caused by NewConnectionError('<urllib3.connection.HTTPSConnection object at 0xf5a2f6b0>: Failed to establish a new connection: [Errno 101] Network is unreachable')) (ConnectionError).",
        "severity": 3,
        "origin": "heating_control.py/get_and_export_system_state:140 --> project.py/write:280 --> project.py/interact:260",
        "origin_timestamp": "2024-10-17-02-38-20",
        "registration_timestamp": "2024-10-17-02-38-20",
        "reported": true,
        "reported_timestamp": "2024-10-17-02-40-05",
        "checked": false,
        "checked_timestamp": null
    },
    {
        "message": "Unexpected error while exporting system state: name 'system_node' is not defined.",
        "severity": 3,
        "origin": "heating_control.py/get_and_export_system_state:140",
        "origin_timestamp": "2024-10-17-22-05-09",
        "registration_timestamp": "2024-10-17-22-05-09",
        "reported": true,
        "reported_timestamp": "2024-10-17-22-10-05",
        "checked": false,
        "checked_timestamp": null
    },
    {
        "message": "Unexpected error while voting: name 'system_node' is not defined.",
        "severity": 3,
        "origin": "heating_control.py/compare_and_command:279",
        "origin_timestamp": "2024-10-17-22-05-09",
        "registration_timestamp": "2024-10-17-22-05-09",
        "reported": true,
        "reported_timestamp": "2024-10-17-22-10-08",
        "checked": false,
        "checked_timestamp": null
    },
    {
        "message": "Unexpected error while issuing commands: name 'COMMANDS_PATH' is not defined.",
        "severity": 3,
        "origin": "heating_control.py/compare_and_command:315",
        "origin_timestamp": "2024-10-17-22-05-09",
        "registration_timestamp": "2024-10-17-22-05-09",
        "reported": true,
        "reported_timestamp": "2024-10-17-22-10-10",
        "checked": false,
        "checked_timestamp": null
    },
    {
        "message": "Unexpected error while executing commands: name 'COMMANDS_PATH' is not defined.",
        "severity": 3,
        "origin": "heating_control.py/execute_commands:378",
        "origin_timestamp": "2024-10-17-22-05-09",
        "registration_timestamp": "2024-10-17-22-05-09",
        "reported": true,
        "reported_timestamp": "2024-10-17-22-10-11",
        "checked": false,
        "checked_timestamp": null
    },
    {
        "message": "Unexpected error while voting: 'measured_temps'.",
        "severity": 3,
        "origin": "heating_control.py/compare_and_command:186",
        "origin_timestamp": "2024-10-17-22-37-40",
        "registration_timestamp": "2024-10-17-22-37-40",
        "reported": true,
        "reported_timestamp": "2024-10-17-22-40-08",
        "checked": false,
        "checked_timestamp": null
    },
    {
        "message": "Module error while trying to scrape and log external temperature: failed to interact with node 'system' via patch: Object of type JSONNodeAtURL is not JSON serializable (TypeError).",
        "severity": 2,
        "origin": "external_temp_scraper_and_logger.py:11 --> project.py/write:280 --> project.py/interact:260",
        "origin_timestamp": "2024-10-22-12-29-43",
        "registration_timestamp": "2024-10-22-12-29-43",
        "reported": true,
        "reported_timestamp": "2024-10-22-12-30-06",
        "checked": false,
        "checked_timestamp": null
    },
    {
        "message": "Module error while trying to update local copy of override_cycles: failed to set up Google Sheets API: The read operation timed out (TimeoutError).",
        "severity": 3,
        "origin": "schedule_and_config_updater.py/update_local_scheduling_files:170 --> project.py/download_google_sheet_to_2D_array:1520",
        "origin_timestamp": "2024-10-29-04-41-09",
        "registration_timestamp": "2024-10-29-04-41-09",
        "reported": true,
        "reported_timestamp": "2024-10-29-04-45-08",
        "checked": false,
        "checked_timestamp": null
    },
    {
        "message": "Couldn't generate system switch: 'room_11_on'.",
        "severity": 0,
        "origin": "schedule_and_config_updater.py/generate_and_export_heating_switch:123 --> schedule_and_config_updater.py/<dictcomp>:123",
        "origin_timestamp": "2024-10-30-14-58-48",
        "registration_timestamp": "2024-10-30-14-58-48",
        "reported": true,
        "reported_timestamp": "2024-10-30-15-00-08",
        "checked": false,
        "checked_timestamp": null
    },
    {
        "message": "Module error while trying to update local copy of weekly_cycle/11: requested sheet 'Oktopusz ker\u00e1mia 1' not in spreadsheet 'f\u0171t\u00e9s heti ciklus 24/25'.",
        "severity": 3,
        "origin": "schedule_and_config_updater.py/update_local_scheduling_files:171 --> project.py/download_google_sheet_to_2D_array:1547",
        "origin_timestamp": "2024-10-30-14-59-13",
        "registration_timestamp": "2024-10-30-14-59-13",
        "reported": true,
        "reported_timestamp": "2024-10-30-15-00-10",
        "checked": false,
        "checked_timestamp": null
    },
    {
        "message": "Module error while trying to generate condensed schedule: couldn't load csv from config/scheduling/local_scheduling_files/weekly_cycle_room_11.csv: [Errno 2] No such file or directory: '/media/pi/program_stick/kazanfutes/config/scheduling/local_scheduling_files/weekly_cycle_room_11.csv' (FileNotFoundError).",
        "severity": 3,
        "origin": "schedule_and_config_updater.py/generate_condensed_schedule:251 --> project.py/load_csv_to_2D_array:1589",
        "origin_timestamp": "2024-10-30-14-59-25",
        "registration_timestamp": "2024-10-30-14-59-25",
        "reported": true,
        "reported_timestamp": "2024-10-30-15-00-11",
        "checked": false,
        "checked_timestamp": null
    },
    {
        "message": "Module error while trying to update local copy of weekly_cycle/1: failed to set up Google Sheets API: <HttpError 503 when requesting https://sheets.googleapis.com/v4/spreadsheets/1OmcLOB4OvFqmVw6Jq1lxu5fo7FchPBNMM6MFoNgM7r4?alt=json returned \"The service is currently unavailable.\". Details: \"The service is currently unavailable.\"> (HttpError).",
        "severity": 3,
        "origin": "schedule_and_config_updater.py/update_local_scheduling_files:171 --> project.py/download_google_sheet_to_2D_array:1543",
        "origin_timestamp": "2024-11-01-18-36-56",
        "registration_timestamp": "2024-11-01-18-36-56",
        "reported": true,
        "reported_timestamp": "2024-11-01-18-40-06",
        "checked": false,
        "checked_timestamp": null
    },
    {
        "message": "Module error while trying to scrape and log external temperature: error during external temperature scraping: HTTPSConnectionPool(host='api.open-meteo.com', port=443): Max retries exceeded with url: /v1/forecast?latitude=47.4984&longitude=19.0405&current_weather=true (Caused by NewConnectionError('<urllib3.connection.HTTPSConnection object at 0xf5812ab0>: Failed to establish a new connection: [Errno 101] Network is unreachable')) (ConnectionError).",
        "severity": 2,
        "origin": "external_temp_scraper_and_logger.py:9 --> project.py/scrape_external_temperature:618",
        "origin_timestamp": "2024-11-07-12-42-19",
        "registration_timestamp": "2024-11-07-12-42-19",
        "reported": true,
        "reported_timestamp": "2024-11-07-12-45-05",
        "checked": false,
        "checked_timestamp": null
    },
    {
        "message": "Module error while trying to scrape and log external temperature: failed to interact with node 'system' via get: HTTPSConnectionPool(host='kazanfutes-71b78-default-rtdb.europe-west1.firebasedatabase.app', port=443): Max retries exceeded with url: /system/.json (Caused by SSLError(SSLZeroReturnError(6, 'TLS/SSL connection has been closed (EOF) (_ssl.c:992)'))) (SSLError).",
        "severity": 2,
        "origin": "external_temp_scraper_and_logger.py:10 --> project.py/__init__:240 --> project.py/read:266 --> project.py/interact:260",
        "origin_timestamp": "2024-11-07-20-15-10",
        "registration_timestamp": "2024-11-07-20-15-10",
        "reported": true,
        "reported_timestamp": "2024-11-07-20-20-04",
        "checked": false,
        "checked_timestamp": null
    },
    {
        "message": "Module error while trying to update local heating control config: failed to set up Google Sheets API: Unable to find the server at sheets.googleapis.com (ServerNotFoundError).",
        "severity": 2,
        "origin": "schedule_and_config_updater.py/update_local_heating_control_config:86 --> project.py/download_google_sheet_to_2D_array:1543",
        "origin_timestamp": "2024-11-08-15-23-21",
        "registration_timestamp": "2024-11-08-15-23-21",
        "reported": true,
        "reported_timestamp": "2024-11-08-15-25-06",
        "checked": false,
        "checked_timestamp": null
    },
    {
        "message": "Module error while trying to update local copy of override_rooms: failed to download sheet '<googleapiclient.discovery.Resource object at 0xf492dd70>' from spreadsheet 'f\u0171t\u00e9s id\u0151z\u00edtett k\u00e9r\u00e9s 24/25 (Responses)': The read operation timed out (TimeoutError).",
        "severity": 3,
        "origin": "schedule_and_config_updater.py/update_local_scheduling_files:171 --> project.py/download_google_sheet_to_2D_array:1565",
        "origin_timestamp": "2024-11-23-11-10-50",
        "registration_timestamp": "2024-11-23-11-10-50",
        "reported": true,
        "reported_timestamp": "2024-11-23-11-15-07",
        "checked": false,
        "checked_timestamp": null
    },
    {
        "message": "Module error while trying to acquire temperature and humidity data: couldn't read sensor state due to: failed to connect to Deconz API due to unexpected error: Error requesting data from 192.168.29.54: Cannot connect to host 192.168.29.54:80 ssl:default [Network is unreachable] (RequestError) (ModuleException).",
        "severity": 3,
        "origin": "temperature_and_humidity_logger.py:10 --> project.py/get_room_temps_and_humidity:800",
        "origin_timestamp": "2024-12-03-15-58-56",
        "registration_timestamp": "2024-12-03-15-58-56",
        "reported": true,
        "reported_timestamp": "2024-12-03-16-00-12",
        "checked": false,
        "checked_timestamp": null
    },
    {
        "message": "Module error while trying to sync data and config with repo: git command failed: Command '['git', 'push', '-u', 'origin', 'main']' returned non-zero exit status 128. (CalledProcessError).",
        "severity": 2,
        "origin": "data_and_config_uploader.py:10 --> project.py/sync_dir_with_repo:371",
        "origin_timestamp": "2024-12-15-00-02-37",
        "registration_timestamp": "2024-12-15-00-02-37",
        "reported": true,
        "reported_timestamp": "2024-12-15-00-05-04",
        "checked": false,
        "checked_timestamp": null
    }
]