{"timestamp": "2024-11-07-12-45-05", "message": "Module error while trying to scrape and log external temperature: error during external temperature scraping: HTTPSConnectionPool(host='api.open-meteo.com', port=443): Max retries exceeded with url: /v1/forecast?latitude=47.4984&longitude=19.0405&current_weather=true (Caused by NewConnectionError('<urllib3.connection.HTTPSConnection object at 0xf5812ab0>: Failed to establish a new connection: [Errno 101] Network is unreachable')) (ConnectionError).", "severity": 2, "origin": "external_temp_scraper_and_logger.py:9 --> project.py/scrape_external_temperature:618", "origin_timestamp": "2024-11-07-12-42-19", "registration_timestamp": "2024-11-07-12-42-19"}
{"timestamp": "2024-11-07-20-20-04", "message": "Module error while trying to scrape and log external temperature: failed to interact with node 'system' via get: HTTPSConnectionPool(host='kazanfutes-71b78-default-rtdb.europe-west1.firebasedatabase.app', port=443): Max retries exceeded with url: /system/.json (Caused by SSLError(SSLZeroReturnError(6, 'TLS/SSL connection has been closed (EOF) (_ssl.c:992)'))) (SSLError).", "severity": 2, "origin": "external_temp_scraper_and_logger.py:10 --> project.py/__init__:240 --> project.py/read:266 --> project.py/interact:260", "origin_timestamp": "2024-11-07-20-15-10", "registration_timestamp": "2024-11-07-20-15-10"}
