{"timestamp": "2024-12-15-00-05-04", "message": "Module error while trying to sync data and config with repo: git command failed: Command '['git', 'push', '-u', 'origin', 'main']' returned non-zero exit status 128. (CalledProcessError).", "severity": 2, "origin": "data_and_config_uploader.py:10 --> project.py/sync_dir_with_repo:371", "origin_timestamp": "2024-12-15-00-02-37", "registration_timestamp": "2024-12-15-00-02-37"}
