{"timestamp": "2024-10-16-12-35-02", "message": "Module error while trying to sync data and config with repo: git command failed: Command '['git', 'pull', 'origin', 'main']' returned non-zero exit status 1. (CalledProcessError).", "severity": 2, "origin": "data_and_config_uploader.py:9 --> project.py/sync_dir_with_repo:371", "origin_timestamp": "2024-10-16-12-30-06", "registration_timestamp": "2024-10-16-12-30-06"}
{"timestamp": "2024-10-16-18-00-05", "message": "Module error while acquiring boiler state: couldn't read boiler state: couldn't read state of GPIO pin 4: unexpected error while loading system/GPIO_state.json to dict: Expecting value: line 1 column 1 (char 0) (JSONDecodeError) (ModuleException) (ModuleException).", "severity": 3, "origin": "heating_control.py/get_and_export_system_state:126 --> project.py/get_boiler_state:635", "origin_timestamp": "2024-10-16-17-55-03", "registration_timestamp": "2024-10-16-17-55-03"}
{"timestamp": "2024-10-16-18-00-08", "message": "Unexpected error while voting: 'boiler_state'.", "severity": 3, "origin": "heating_control.py/compare_and_command:276", "origin_timestamp": "2024-10-16-17-55-03", "registration_timestamp": "2024-10-16-17-55-03"}
{"timestamp": "2024-10-16-18-00-10", "message": "Unexpected error while issuing commands: 'boiler_state'.", "severity": 3, "origin": "heating_control.py/compare_and_command:323", "origin_timestamp": "2024-10-16-17-55-03", "registration_timestamp": "2024-10-16-17-55-03"}
