{"timestamp": "2024-10-15-00-00-03", "message": "Unexpected error while trying to update local heating control config: cannot access local variable 'spreadsheet_metadata' where it is not associated with a value.", "severity": 2, "origin": "schedule_and_ config_updater.py/update_local_heating_control_config:56 --> project.py/download_google_sheet_to_2D_array:1523", "origin_timestamp": "2024-10-14-21-45-35", "registration_timestamp": "2024-10-14-21-45-35"}
{"timestamp": "2024-10-15-00-00-03", "message": "Unexpected error while trying to update local copy of weekly_cycle/1: download_csv_to_2D_array() takes 1 positional argument but 2 were given.", "severity": 3, "origin": "schedule_and_ config_updater.py/update_local_scheduling_files:138", "origin_timestamp": "2024-10-14-21-45-35", "registration_timestamp": "2024-10-14-21-45-35"}
{"timestamp": "2024-10-15-00-00-03", "message": "Module error while trying to update local copy of override_rooms: failed to set up Google Sheets API: <HttpError 404 when requesting https://sheets.googleapis.com/v4/spreadsheets/https%3A%2F%2Fdocs.google.com%2Fspreadsheets%2Fd%2F1Cir4TYYhIx14Qja9c4nN9m2GTeZ0FHrJRt03oXs_fgI%2Fpub%3Foutput%3Dcsv?alt=json returned \"Requested entity was not found.\". Details: \"Requested entity was not found.\"> (HttpError).", "severity": 3, "origin": "schedule_and_ config_updater.py/update_local_scheduling_files:138 --> project.py/download_google_sheet_to_2D_array:1501", "origin_timestamp": "2024-10-14-21-54-34", "registration_timestamp": "2024-10-14-21-54-34"}
{"timestamp": "2024-10-15-00-00-03", "message": "Module error while trying to update local copy of weekly_cycle/8: failed to download sheet 'kisterem' from spreadsheet 'f\u0171t\u00e9s heti ciklus 24/25':  (KeyboardInterrupt).", "severity": 3, "origin": "schedule_and_ config_updater.py/update_local_scheduling_files:138 --> project.py/download_google_sheet_to_2D_array:1523", "origin_timestamp": "2024-10-14-22-05-35", "registration_timestamp": "2024-10-14-22-05-35"}
{"timestamp": "2024-10-15-09-21-34", "message": "Module error while trying to acquire temperature and humidity data: couldn't read sensor state due to: failed to connect to Deconz API due to unexpected error: Error requesting data from 192.168.29.54: Cannot connect to host 192.168.29.54:80 ssl:default [Network is unreachable] (RequestError) (ModuleException).", "severity": 3, "origin": "temperature_and_humidity_logger.py:10 --> project.py/get_room_temps_and_humidity:775", "origin_timestamp": "2024-10-15-09-21-34", "registration_timestamp": "2024-10-15-09-21-34"}
{"timestamp": "2024-10-15-09-21-34", "message": "Module error while trying to initialize heating control: failed to interact with node 'system' via get: HTTPSConnectionPool(host='kazanfutes-71b78-default-rtdb.europe-west1.firebasedatabase.app', port=443): Max retries exceeded with url: /system/.json (Caused by NameResolutionError(\"<urllib3.connection.HTTPSConnection object at 0xf5766490>: Failed to resolve 'kazanfutes-71b78-default-rtdb.europe-west1.firebasedatabase.app' ([Errno -3] Temporary failure in name resolution)\")) (ConnectionError).", "severity": 3, "origin": "heating_control.py:15 --> project.py/__init__:240 --> project.py/read:266 --> project.py/interact:260", "origin_timestamp": "2024-10-15-09-21-34", "registration_timestamp": "2024-10-15-09-21-34"}
{"timestamp": "2024-10-15-09-25-04", "message": "Unexpected error while voting: 'measured_temps'.", "severity": 3, "origin": "heating_control.py/compare_and_command:182", "origin_timestamp": "2024-10-15-09-21-34", "registration_timestamp": "2024-10-15-09-21-34"}
{"timestamp": "2024-10-15-09-25-04", "message": "Unexpected error while issuing commands: name 'COMMANDS_PATH' is not defined.", "severity": 3, "origin": "heating_control.py/compare_and_command:309", "origin_timestamp": "2024-10-15-09-21-34", "registration_timestamp": "2024-10-15-09-21-34"}
{"timestamp": "2024-10-15-09-25-04", "message": "Unexpected error while executing commands: name 'COMMANDS_PATH' is not defined.", "severity": 3, "origin": "heating_control.py/execute_commands:372", "origin_timestamp": "2024-10-15-09-21-34", "registration_timestamp": "2024-10-15-09-21-34"}
{"timestamp": "2024-10-15-09-25-04", "message": "Module error while acquiring measured temps: couldn't read sensor state due to: failed to connect to Deconz API due to unexpected error: Error requesting data from 192.168.29.54: Cannot connect to host 192.168.29.54:80 ssl:default [Connect call failed ('192.168.29.54', 80)] (RequestError) (ModuleException).", "severity": 3, "origin": "heating_control.py/get_and_export_system_state:64 --> project.py/get_room_temps_and_humidity:775", "origin_timestamp": "2024-10-15-09-22-19", "registration_timestamp": "2024-10-15-09-22-19"}
{"timestamp": "2024-10-15-09-25-04", "message": "Unexpected error while issuing commands: cannot access local variable 'pump_votes' where it is not associated with a value.", "severity": 3, "origin": "heating_control.py/compare_and_command:314", "origin_timestamp": "2024-10-15-09-22-19", "registration_timestamp": "2024-10-15-09-22-19"}
{"timestamp": "2024-10-15-09-25-04", "message": "Module error while acquiring measured temps: unexpected error while reading sensor state: time data 'none' does not match format '%Y-%m-%dT%H:%M:%S.%f' (ValueError).", "severity": 3, "origin": "heating_control.py/get_and_export_system_state:64 --> project.py/get_room_temps_and_humidity:777", "origin_timestamp": "2024-10-15-09-23-02", "registration_timestamp": "2024-10-15-09-23-02"}
{"timestamp": "2024-10-15-09-25-04", "message": "Unexpected error while exporting system state: name 'system_node' is not defined.", "severity": 3, "origin": "heating_control.py/get_and_export_system_state:136", "origin_timestamp": "2024-10-15-09-21-34", "registration_timestamp": "2024-10-15-09-25-04"}
{"timestamp": "2024-10-15-12-45-07", "message": "Unexpected error while voting: type datetime.timedelta doesn't define __round__ method.", "severity": 3, "origin": "heating_control.py/compare_and_command:194", "origin_timestamp": "2024-10-15-12-42-49", "registration_timestamp": "2024-10-15-12-42-49"}
{"timestamp": "2024-10-15-12-45-07", "message": "Unexpected error while issuing commands: cannot access local variable 'pump_votes' where it is not associated with a value.", "severity": 3, "origin": "heating_control.py/compare_and_command:320", "origin_timestamp": "2024-10-15-12-42-49", "registration_timestamp": "2024-10-15-12-42-49"}
{"timestamp": "2024-10-15-20-50-04", "message": "Module error while trying to capture heatmeter images: couldn't extract cycle crops for None: time data 'None' does not match format '%Y-%m-%d-%H-%M-%S' (ValueError).", "severity": 2, "origin": "heatmeters_logger.py:15 --> project.py/generate_and_save_cycle_crops:626", "origin_timestamp": null, "registration_timestamp": null}
{"timestamp": "2024-10-15-20-50-04", "message": "Module error while trying to update local copy of weekly_cycle/4: failed to download sheet 'SZGK' from spreadsheet 'f\u0171t\u00e9s heti ciklus 24/25':  (KeyboardInterrupt).", "severity": 3, "origin": "schedule_and_config_updater.py/update_local_scheduling_files:167 --> project.py/download_google_sheet_to_2D_array:1533", "origin_timestamp": null, "registration_timestamp": null}
{"timestamp": "2024-10-15-20-50-06", "message": "Module error while trying to update local copy of weekly_cycle/8: failed to set up Google Sheets API:  (KeyboardInterrupt).", "severity": 3, "origin": "schedule_and_config_updater.py/update_local_scheduling_files:167 --> project.py/download_google_sheet_to_2D_array:1511", "origin_timestamp": null, "registration_timestamp": null}
