{"timestamp": "2025-02-05-11-15-06", "message": "Module error while trying to scrape and log external temperature: failed to interact with node 'system' via get: HTTPSConnectionPool(host='kazanfutes-71b78-default-rtdb.europe-west1.firebasedatabase.app', port=443): Max retries exceeded with url: /system/.json (Caused by NewConnectionError('<urllib3.connection.HTTPSConnection object at 0xf53b1190>: Failed to establish a new connection: [Errno 101] Network is unreachable')) (ConnectionError).", "severity": 2, "origin": "external_temp_scraper_and_logger.py:10 --> project.py/__init__:245 --> project.py/read:271 --> project.py/interact:265", "origin_timestamp": "2025-02-05-11-12-21", "registration_timestamp": "2025-02-05-11-12-21"}
{"timestamp": "2025-02-05-16-25-04", "message": "Module error while trying to sync data and config with repo: git command failed: Command '['git', 'add', '.']' died with <Signals.SIGBUS: 7>. (CalledProcessError).", "severity": 2, "origin": "data_and_config_uploader.py:10 --> project.py/sync_dir_with_repo:372", "origin_timestamp": "2025-02-05-16-20-20", "registration_timestamp": "2025-02-05-16-20-20"}
{"timestamp": "2025-02-05-17-25-04", "message": "Module error while trying to sync services and utils with repo: Lock file exists and is fresh. Aborting sync to avoid conflicts. (/media/pi/program_stick/kazanfutes/.git/index.lock).", "severity": 2, "origin": "services_and_utils_syncer.py:9 --> project.py/check_index_lock:395", "origin_timestamp": "2025-02-05-17-20-18", "registration_timestamp": "2025-02-05-17-20-18"}
