{"timestamp": "2025-02-09-00-40-07", "message": "Module error while trying to scrape and log external temperature: error during external temperature scraping: HTTPSConnectionPool(host='api.open-meteo.com', port=443): Max retries exceeded with url: /v1/forecast?latitude=47.4984&longitude=19.0405&current_weather=true (Caused by NewConnectionError('<urllib3.connection.HTTPSConnection object at 0xf57dae10>: Failed to establish a new connection: [Errno 101] Network is unreachable')) (ConnectionError).", "severity": 2, "origin": "external_temp_scraper_and_logger.py:9 --> project.py/scrape_external_temperature:644", "origin_timestamp": "2025-02-09-00-37-20", "registration_timestamp": "2025-02-09-00-37-20"}
