{"timestamp": "2025-01-22-00-05-05", "message": "Module error while trying to sync data and config with repo: git command failed: Command '['git', 'add', '.']' returned non-zero exit status 128. (CalledProcessError).", "severity": 2, "origin": "data_and_config_uploader.py:9 --> project.py/sync_dir_with_repo:375", "origin_timestamp": "2025-01-22-00-00-13", "registration_timestamp": "2025-01-22-00-00-13"}
