{"timestamp": "2024-10-16-12-35-02", "message": "Module error while trying to sync data and config with repo: git command failed: Command '['git', 'pull', 'origin', 'main']' returned non-zero exit status 1. (CalledProcessError).", "severity": 2, "origin": "data_and_config_uploader.py:9 --> project.py/sync_dir_with_repo:371", "origin_timestamp": "2024-10-16-12-30-06", "registration_timestamp": "2024-10-16-12-30-06"}
