{"timestamp": "2024-09-23-11-23-02", "message": "Module error while trying to sync data with repo: git command failed: Command '['git', 'pull', 'origin', 'main']' returned non-zero exit status 1. (CalledProcessError).", "severity": 2, "origin": "data_uploader.py:9 --> project.py/sync_dir_with_repo:257", "origin_timestamp": "2024-09-23-11-22-42", "registration_timestamp": "2024-09-23-11-22-42", "reported": false, "reported_timestamp": null, "checked": false, "checked_timestamp": null}
