{"timestamp": "2025-01-22-00-05-05", "message": "Module error while trying to sync data and config with repo: git command failed: Command '['git', 'add', '.']' returned non-zero exit status 128. (CalledProcessError).", "severity": 2, "origin": "data_and_config_uploader.py:9 --> project.py/sync_dir_with_repo:375", "origin_timestamp": "2025-01-22-00-00-13", "registration_timestamp": "2025-01-22-00-00-13"}
{"timestamp": "2025-01-22-04-30-05", "message": "Module error while trying to initialize heating control: failed to interact with node 'system' via get: HTTPSConnectionPool(host='kazanfutes-71b78-default-rtdb.europe-west1.firebasedatabase.app', port=443): Max retries exceeded with url: /system/.json (Caused by NewConnectionError('<urllib3.connection.HTTPSConnection object at 0xf56e2a30>: Failed to establish a new connection: [Errno 101] Network is unreachable')) (ConnectionError).", "severity": 3, "origin": "heating_control.py:15 --> project.py/__init__:244 --> project.py/read:270 --> project.py/interact:264", "origin_timestamp": "2025-01-22-04-26-26", "registration_timestamp": "2025-01-22-04-26-26"}
{"timestamp": "2025-01-22-14-30-07", "message": "Module error while trying to update local copy of weekly_cycle/1: failed to set up Google Sheets API: <HttpError 500 when requesting https://sheets.googleapis.com/v4/spreadsheets/1OmcLOB4OvFqmVw6Jq1lxu5fo7FchPBNMM6MFoNgM7r4?alt=json returned \"Internal error encountered.\". Details: \"Internal error encountered.\"> (HttpError).", "severity": 3, "origin": "schedule_and_config_updater.py/update_local_scheduling_files:171 --> project.py/download_google_sheet_to_2D_array:1596", "origin_timestamp": "2025-01-22-14-30-06", "registration_timestamp": "2025-01-22-14-30-06"}
{"timestamp": "2025-01-22-14-55-06", "message": "Module error while trying to update condensed schedule to Firebase: failed to interact with node 'schedule' via patch: HTTPSConnectionPool(host='kazanfutes-71b78-default-rtdb.europe-west1.firebasedatabase.app', port=443): Max retries exceeded with url: /schedule/.json (Caused by SSLError(SSLZeroReturnError(6, 'TLS/SSL connection has been closed (EOF) (_ssl.c:992)'))) (SSLError).", "severity": 2, "origin": "schedule_and_config_updater.py/update_condensed_schedule_on_firebase:331 --> project.py/write:284 --> project.py/interact:264", "origin_timestamp": "2025-01-22-14-54-26", "registration_timestamp": "2025-01-22-14-54-26"}
{"timestamp": "2025-01-22-21-45-10", "message": "Module error while trying to update local copy of weekly_cycle/1: failed to set up Google Sheets API: <HttpError 503 when requesting https://sheets.googleapis.com/v4/spreadsheets/1OmcLOB4OvFqmVw6Jq1lxu5fo7FchPBNMM6MFoNgM7r4?alt=json returned \"The service is currently unavailable.\". Details: \"The service is currently unavailable.\"> (HttpError).", "severity": 3, "origin": "schedule_and_config_updater.py/update_local_scheduling_files:173 --> project.py/download_google_sheet_to_2D_array:1596", "origin_timestamp": "2025-01-22-21-40-15", "registration_timestamp": "2025-01-22-21-40-15"}
{"timestamp": "2025-01-22-23-45-05", "message": "Module error while trying to update local heating control config: failed to download sheet '<googleapiclient.discovery.Resource object at 0xf49b9c30>' from spreadsheet 'Kaz\u00e1nf\u0171t\u00e9s heating control config': <HttpError 503 when requesting https://sheets.googleapis.com/v4/spreadsheets/1sXoPC301Wurbm7yW5A956dlFEJcwM-fIb090fKOxROw/values/Sheet1%21A1%3AZ10000?alt=json returned \"The service is currently unavailable.\". Details: \"The service is currently unavailable.\"> (HttpError).", "severity": 2, "origin": "schedule_and_config_updater.py/update_local_heating_control_config:88 --> project.py/download_google_sheet_to_2D_array:1618", "origin_timestamp": "2025-01-22-23-41-33", "registration_timestamp": "2025-01-22-23-41-33"}
{"timestamp": "2025-01-23-17-13-36", "message": "Module error while trying to update local heating control config: failed to set up Google Sheets API: [Errno 2] No such file or directory: '/media/pi/program_stick/kazanfutes/config/secrets_and_env/sheets-access-key.json' (FileNotFoundError).", "severity": 2, "origin": "schedule_and_config_updater.py/update_local_heating_control_config:88 --> project.py/download_google_sheet_to_2D_array:1596", "origin_timestamp": "2025-01-23-17-05-44", "registration_timestamp": "2025-01-23-17-05-44"}
{"timestamp": "2025-01-23-17-25-05", "message": "Module error while trying to scrape and log external temperature: error during external temperature scraping: HTTPSConnectionPool(host='api.open-meteo.com', port=443): Max retries exceeded with url: /v1/forecast?latitude=47.4984&longitude=19.0405&current_weather=true (Caused by NameResolutionError(\"<urllib3.connection.HTTPSConnection object at 0xf53b4ab0>: Failed to resolve 'api.open-meteo.com' ([Errno -3] Temporary failure in name resolution)\")) (ConnectionError).", "severity": 2, "origin": "external_temp_scraper_and_logger.py:9 --> project.py/scrape_external_temperature:622", "origin_timestamp": "2025-01-23-17-20-26", "registration_timestamp": "2025-01-23-17-20-26"}
